<?xml version="2.0"?>
<robot xmlns:xacro="http://ros.org/wiki/xacro">


  <!-- A macro to create a screw tool. The param "prefix" is not yet implemented -->
  <xacro:macro name="screw_tool" params="prefix">
  
    <!-- include the ft-sensor -->
    <xacro:include filename="$(find rl_gazebo_sim)/parts_descriptions/screw_tool/ft_sensor.urdf"/>

    <!-- Include the drill and mount -->
    <xacro:include filename="$(find rl_gazebo_sim)/parts_descriptions/screw_tool/drill.urdf"/> 

    <!-- Add the drill to the ft_sensor -->
    <joint name="ft_sensor_drill_joint" type="fixed">
      <origin xyz="0 0 0.06342" rpy="0.0 0.0 ${pi/4}"/>
      <parent link="ft_sensor"/>
      <child link="drill"/>
    </joint>

    <!-- Activate the feedback and make sure the joint dont get reduced because it's fixed.-->
    <gazebo reference="ft_sensor_drill_joint">
      <disableFixedJointLumping>true</disableFixedJointLumping>
      <provideFeedback>true</provideFeedback>
    </gazebo>

    <!-- FT sensor plugin-->    
    <gazebo>    
      <plugin name="FTsensor_controller"    filename="libgazebo_ros_ft_sensor.so">
        <updateRate>100.0</updateRate>
        <topicName>FTsensor_topic</topicName>
        <gaussianNoise>0.0</gaussianNoise>
        <jointName>ft_sensor_drill_joint</jointName>
      </plugin>    
    </gazebo>


    <!-- include the screw bit-->
    <xacro:include filename="$(find rl_gazebo_sim)/parts_descriptions/screw_tool/ScrewDriverBit.urdf"/>

    <!-- add the screw bit to the screw machine-->
    <joint name="drill_ScrewDriverBitStar_joint" type="revolute">
      <origin xyz="0  0 0.147" rpy="0 0 0" /> <!--162mm but sunken 15mm in to the bit holder -->
      <parent link="drill"/>
      <child link="ScrewDriverBitStar"/>
      <axis xyz="0 0 1"/>
      <limit velocity="1000" effort="1" lower="-100" upper="100"/>     
      </joint>

    <!-- Frame coincident with the tip of the screw driver bit -->
    <link name="ee_tip"/>
    <joint name="ScrewDriverBitStar_ee_tip" type="fixed">
      <origin xyz="0 0 0.025" rpy="0 0 0"/>
      <parent link="ScrewDriverBitStar"/>
      <child link="ee_tip"/> 
      </joint>

    <!--dont reduce the fixed joint -->
    <gazebo reference="ee_tip">
      <disableFixedJointLumping>true</disableFixedJointLumping>
    </gazebo>

    <!-- 
      add transmision to the screw_tool so it can be controlled by ros
      it is added to the same hardware_interface as the ur robot so it
      is the same namespace 
    -->
    <transmission name="screw_tool_trans">
      <type>transmission_interface/SimpleTransmission</type>
      <joint name="drill_ScrewDriverBitStar_joint">
        <hardwareInterface>hardware_interface/PositionJointInterface</hardwareInterface>
      </joint>
      <actuator name="screw_motor">
        <mechanicalReduction>1</mechanicalReduction>
      </actuator>
    </transmission>

  </xacro:macro>
</robot>

